<?xml version="1.0" encoding="UTF-8"?>
<!-- Generated by org.testng.reporters.JUnitReportReporter -->
<testsuite hostname="EPRURYAW0075" name="com.epam.vyacheslav_utenkov.java.lesson7.advanced.YandexMailTest" tests="8" failures="0" timestamp="13 Sep 2016 13:05:00 GMT" time="49.814" errors="1">
  <testcase name="sendMessagesTest" time="3.606" classname="com.epam.vyacheslav_utenkov.java.lesson7.advanced.YandexMailTest"/>
  <testcase name="getException" time="0.162" classname="com.epam.vyacheslav_utenkov.java.lesson7.advanced.YandexMailTest">
    <error type="java.lang.RuntimeException">
      <![CDATA[java.lang.RuntimeException
	at com.epam.vyacheslav_utenkov.java.lesson7.advanced.YandexMailTest.getException(YandexMailTest.java:144)
	at sun.reflect.NativeMethodAccessorImpl.invoke0(Native Method)
	at sun.reflect.NativeMethodAccessorImpl.invoke(NativeMethodAccessorImpl.java:62)
	at sun.reflect.DelegatingMethodAccessorImpl.invoke(DelegatingMethodAccessorImpl.java:43)
	at java.lang.reflect.Method.invoke(Method.java:498)
	at org.testng.internal.MethodInvocationHelper.invokeMethod(MethodInvocationHelper.java:85)
	at org.testng.internal.Invoker.invokeMethod(Invoker.java:639)
	at org.testng.internal.Invoker.invokeTestMethod(Invoker.java:816)
	at org.testng.internal.Invoker.invokeTestMethods(Invoker.java:1124)
	at org.testng.internal.TestMethodWorker.invokeTestMethods(TestMethodWorker.java:125)
	at org.testng.internal.TestMethodWorker.run(TestMethodWorker.java:108)
	at org.testng.TestRunner.privateRun(TestRunner.java:774)
	at org.testng.TestRunner.run(TestRunner.java:624)
	at org.testng.SuiteRunner.runTest(SuiteRunner.java:359)
	at org.testng.SuiteRunner.runSequentially(SuiteRunner.java:354)
	at org.testng.SuiteRunner.privateRun(SuiteRunner.java:312)
	at org.testng.SuiteRunner.run(SuiteRunner.java:261)
	at org.testng.SuiteRunnerWorker.runSuite(SuiteRunnerWorker.java:52)
	at org.testng.SuiteRunnerWorker.run(SuiteRunnerWorker.java:86)
	at org.testng.TestNG.runSuitesSequentially(TestNG.java:1215)
	at org.testng.TestNG.runSuitesLocally(TestNG.java:1140)
	at org.testng.TestNG.run(TestNG.java:1048)
	at org.testng.remote.AbstractRemoteTestNG.run(AbstractRemoteTestNG.java:126)
	at org.testng.remote.RemoteTestNG.initAndRun(RemoteTestNG.java:152)
	at org.testng.remote.RemoteTestNG.main(RemoteTestNG.java:57)
]]>
    </error>
  </testcase> <!-- getException -->
  <testcase name="deleteMessage" time="10.103" classname="com.epam.vyacheslav_utenkov.java.lesson7.advanced.YandexMailTest"/>
  <testcase name="sendMessagesTest" time="4.231" classname="com.epam.vyacheslav_utenkov.java.lesson7.advanced.YandexMailTest"/>
  <testcase name="deleteMessage" time="10.129" classname="com.epam.vyacheslav_utenkov.java.lesson7.advanced.YandexMailTest"/>
  <testcase name="loginTest" time="5.832" classname="com.epam.vyacheslav_utenkov.java.lesson7.advanced.YandexMailTest"/>
  <testcase name="sendMessagesTest" time="5.547" classname="com.epam.vyacheslav_utenkov.java.lesson7.advanced.YandexMailTest"/>
  <testcase name="deleteMessage" time="10.204" classname="com.epam.vyacheslav_utenkov.java.lesson7.advanced.YandexMailTest"/>
</testsuite> <!-- com.epam.vyacheslav_utenkov.java.lesson7.advanced.YandexMailTest -->
